Traceback (most recent call last):
  File "C:\Users\binod\AppData\Roaming\Python\Python310\site-packages\urllib3\connectionpool.py", line 787, in urlopen
    response = self._make_request(
  File "C:\Users\binod\AppData\Roaming\Python\Python310\site-packages\urllib3\connectionpool.py", line 488, in _make_request
    raise new_e
  File "C:\Users\binod\AppData\Roaming\Python\Python310\site-packages\urllib3\connectionpool.py", line 464, in _make_request
    self._validate_conn(conn)
  File "C:\Users\binod\AppData\Roaming\Python\Python310\site-packages\urllib3\connectionpool.py", line 1093, in _validate_conn
    conn.connect()
  File "C:\Users\binod\AppData\Roaming\Python\Python310\site-packages\urllib3\connection.py", line 790, in connect
    sock_and_verified = _ssl_wrap_socket_and_match_hostname(
  File "C:\Users\binod\AppData\Roaming\Python\Python310\site-packages\urllib3\connection.py", line 969, in _ssl_wrap_socket_and_match_hostname
    ssl_sock = ssl_wrap_socket(
  File "C:\Users\binod\AppData\Roaming\Python\Python310\site-packages\urllib3\util\ssl_.py", line 480, in ssl_wrap_socket
    ssl_sock = _ssl_wrap_socket_impl(sock, context, tls_in_tls, server_hostname)
  File "C:\Users\binod\AppData\Roaming\Python\Python310\site-packages\urllib3\util\ssl_.py", line 524, in _ssl_wrap_socket_impl
    return ssl_context.wrap_socket(sock, server_hostname=server_hostname)
  File "C:\Program Files\Python310\lib\ssl.py", line 512, in wrap_socket
    return self.sslsocket_class._create(
  File "C:\Program Files\Python310\lib\ssl.py", line 1070, in _create
    self.do_handshake()
  File "C:\Program Files\Python310\lib\ssl.py", line 1341, in do_handshake
    self._sslobj.do_handshake()
ConnectionResetError: [WinError 10054] An existing connection was forcibly closed by the remote host

During handling of the above exception, another exception occurred:

Traceback (most recent call last):
  File "C:\Users\binod\AppData\Roaming\Python\Python310\site-packages\requests\adapters.py", line 644, in send
    resp = conn.urlopen(
  File "C:\Users\binod\AppData\Roaming\Python\Python310\site-packages\urllib3\connectionpool.py", line 841, in urlopen
    retries = retries.increment(
  File "C:\Users\binod\AppData\Roaming\Python\Python310\site-packages\urllib3\util\retry.py", line 474, in increment
    raise reraise(type(error), error, _stacktrace)
  File "C:\Users\binod\AppData\Roaming\Python\Python310\site-packages\urllib3\util\util.py", line 38, in reraise
    raise value.with_traceback(tb)
  File "C:\Users\binod\AppData\Roaming\Python\Python310\site-packages\urllib3\connectionpool.py", line 787, in urlopen
    response = self._make_request(
  File "C:\Users\binod\AppData\Roaming\Python\Python310\site-packages\urllib3\connectionpool.py", line 488, in _make_request
    raise new_e
  File "C:\Users\binod\AppData\Roaming\Python\Python310\site-packages\urllib3\connectionpool.py", line 464, in _make_request
    self._validate_conn(conn)
  File "C:\Users\binod\AppData\Roaming\Python\Python310\site-packages\urllib3\connectionpool.py", line 1093, in _validate_conn
    conn.connect()
  File "C:\Users\binod\AppData\Roaming\Python\Python310\site-packages\urllib3\connection.py", line 790, in connect
    sock_and_verified = _ssl_wrap_socket_and_match_hostname(
  File "C:\Users\binod\AppData\Roaming\Python\Python310\site-packages\urllib3\connection.py", line 969, in _ssl_wrap_socket_and_match_hostname
    ssl_sock = ssl_wrap_socket(
  File "C:\Users\binod\AppData\Roaming\Python\Python310\site-packages\urllib3\util\ssl_.py", line 480, in ssl_wrap_socket
    ssl_sock = _ssl_wrap_socket_impl(sock, context, tls_in_tls, server_hostname)
  File "C:\Users\binod\AppData\Roaming\Python\Python310\site-packages\urllib3\util\ssl_.py", line 524, in _ssl_wrap_socket_impl
    return ssl_context.wrap_socket(sock, server_hostname=server_hostname)
  File "C:\Program Files\Python310\lib\ssl.py", line 512, in wrap_socket
    return self.sslsocket_class._create(
  File "C:\Program Files\Python310\lib\ssl.py", line 1070, in _create
    self.do_handshake()
  File "C:\Program Files\Python310\lib\ssl.py", line 1341, in do_handshake
    self._sslobj.do_handshake()
urllib3.exceptions.ProtocolError: ('Connection aborted.', ConnectionResetError(10054, 'An existing connection was forcibly closed by the remote host', None, 10054, None))

During handling of the above exception, another exception occurred:

Traceback (most recent call last):
  File "C:\Users\binod\OneDrive\Desktop\AnnieXMusic\ANNIEMUSIC\utils\cookie_handler.py", line 41, in fetch_and_store_cookies
    response = await asyncio.to_thread(
  File "C:\Program Files\Python310\lib\asyncio\threads.py", line 25, in to_thread
    return await loop.run_in_executor(None, func_call)
  File "C:\Program Files\Python310\lib\concurrent\futures\thread.py", line 52, in run
    result = self.fn(*self.args, **self.kwargs)
  File "C:\Users\binod\AppData\Roaming\Python\Python310\site-packages\requests\api.py", line 73, in get
    return request("get", url, params=params, **kwargs)
  File "C:\Users\binod\AppData\Roaming\Python\Python310\site-packages\requests\api.py", line 59, in request
    return session.request(method=method, url=url, **kwargs)
  File "C:\Users\binod\AppData\Roaming\Python\Python310\site-packages\requests\sessions.py", line 589, in request
    resp = self.send(prep, **send_kwargs)
  File "C:\Users\binod\AppData\Roaming\Python\Python310\site-packages\requests\sessions.py", line 703, in send
    r = adapter.send(request, **kwargs)
  File "C:\Users\binod\AppData\Roaming\Python\Python310\site-packages\requests\adapters.py", line 659, in send
    raise ConnectionError(err, request=request)
requests.exceptions.ConnectionError: ('Connection aborted.', ConnectionResetError(10054, 'An existing connection was forcibly closed by the remote host', None, 10054, None))

During handling of the above exception, another exception occurred:

Traceback (most recent call last):
  File "C:\Users\binod\OneDrive\Desktop\AnnieXMusic\ANNIEMUSIC\utils\errors.py", line 133, in wrapper
    return await func(*args, **kwargs)
  File "C:\Users\binod\OneDrive\Desktop\AnnieXMusic\ANNIEMUSIC\utils\cookie_handler.py", line 49, in fetch_and_store_cookies
    raise ConnectionError(f"⚠️ ᴄᴀɴ'ᴛ ꜰᴇᴛᴄʜ ᴄᴏᴏᴋɪᴇs:\n{e}")
ConnectionError: ⚠️ ᴄᴀɴ'ᴛ ꜰᴇᴛᴄʜ ᴄᴏᴏᴋɪᴇs:
('Connection aborted.', ConnectionResetError(10054, 'An existing connection was forcibly closed by the remote host', None, 10054, None))
